Workbook

Sheet TEAM
A1: SI NO | B1: AD NO | C1: NAME | D1: TEAM | E1: CLASS | F1: CATEGARY
A2: 1 | B2: 67 | C2: MUHAMMED ABDUL SALEEM K | D2: TEAM C | E2: 10 | F2: ʿĀLIYAH
A3: 2 | B3: 68 | C3: MUHAMMED SALIM K | D3: TEAM A | E3: 10 | F3: ʿĀLIYAH
A4: 3 | B4: 357 | C4: MUHAMMED ANSAR PK | D4: TEAM B | E4: 10 | F4: ʿĀLIYAH
A5: 4 | B5: 71 | C5: AAKHIL MUHAMMED K | D5: TEAM A | E5: 10 | F5: ʿĀLIYAH
A6: 5 | B6: 393 | C6: MUHAMMED SALMAN OK | D6: TEAM D | E6: 10 | F6: ʿĀLIYAH
A7: 6 | B7: 78 | C7: MUHAMMED FARHAN | D7: TEAM B | E7: 10 | F7: ʿĀLIYAH
A8: 7 | B8: 356 | C8: SHIHAD TK | D8: TEAM C | E8: 10 | F8: ʿĀLIYAH
A9: 8 | B9: 354 | C9: MUHAMMED ALTHAF K | D9: TEAM D | E9: 10 | F9: ʿĀLIYAH
A10: 9 | B10: 56 | C10: MUHAMMED SAHAL KC | D10: TEAM D | E10: 10 | F10: ʿĀLIYAH
A11: 10 | B11: 64 | C11: UNAIS K | D11: TEAM A | E11: 10 | F11: ʿĀLIYAH
A12: 11 | B12: 45 | C12: AKHEEL NASIM | D12: TEAM D | E12: 10 | F12: ʿĀLIYAH
A13: 12 | B13: 66 | C13: MUHAMMED SAFEER MP | D13: TEAM C | E13: 10 | F13: ʿĀLIYAH
... A294: 293 | B294: 487 | C294: RAHIL RAYAN P | D294: TEAM C | E294: 1 | F294: BIDĀYAH

Sheet SPORTS PROGRAM LIST
A1: SPORTS PROGRAM LIST
A2: BIDĀYAH | D2: ŪLĀ | G2: THĀNIYAH | J2: THĀNAWIYYAH | M2: ʿĀLIYAH | P2: KULLIYYAH
A3: Code | B3: Programme Name | C3: No. of Participants | D3: Code | E3: Programme Name | F3: No. of Participants | G3: Code | H3: Programme Name | I3: No. of Participants | J3: Code | K3: Programme Name | L3: No. of Participants | M3: Code | N3: Programme Name | O3: No. of Participants | P3: Code | Q3: Programme Name | R3: No. of Participants
A4: BSP1 | B4: 100M Running | C4: 2 | D4: USP1 | E4: 100M Running | F4: 2 | G4: TSP1 | H4: 200M Running | I4: 2 | J4: TWSP1 | K4: 200M Running | L4: 2 | M4: ASP1 | N4: 400M Running | O4: 2 | P4: KSP1 | Q4: Football | R4: 7 (ALY +TWY)
A5: BSP2 | B5: Long Jump | C5: 2 | D5: USP2 | E5: Long Jump | F5: 2 | G5: TSP2 | H5: Long Jump | I5: 2 | J5: TWSP2 | K5: Long Jump | L5: 2 | M5: ASP2 | N5: Long Jump | O5: 2 | P5: KSP2 | Q5: Volleyball | R5: 7( ALY +TWY)
A6: BSP3 | B6: 4 × 100M Relay | C6: 2 | D6: USP3 | E6: 4 × 100M Relay | F6: 2 | G6: TSP3 | H6: 4 × 100M Relay | I6: 2 | J6: TWSP3 | K6: 4 × 100M Relay | L6: 2 | M6: ASP3 | N6: 4 × 100M Relay | O6: 2 | P6: KSP3 | Q6: Cricket | R6: 6( ALY +TWY)
A7: BSP4 | B7: Lemon & Spoon Race | C7: 2 | D7: USP4 | E7: Sack Race | F7: 2 | G7: TSP4 | H7: Sack Race | I7: 2 | J7: TWSP4 | K7: Shootout | L7: 2 | M7: ASP4 | N7: Shootout | O7: 2 | P7: KSP4 | Q7: Chess | R7: 1
A8: BSP5 | B8: Seed and Needle | C8: 2 | D8: USP5 | E8: Lemon & Spoon Race | F8: 2 | G8: TSP5 | H8: Shootout | I8: 2 | J8: TWSP5 | K8: Push Up | L8: 2 | M8: ASP5 | N8: Push Up | O8: 2
A9: BSP6 | B9: Shootout | C9: 2 | D9: USP6 | E9: Shootout | F9: 2 | G9: TSP6 | H9: Badminton | I9: 2 | J9: TWSP6 | K9: Plank | L9: 2 | M9: ASP6 | N9: Plank | O9: 2
A10: BSP7 | B10: Frog Jump | C10: 2 | D10: USP7 | E10: Badminton | F10: 2 | G10: TSP7 | H10: Plank | I10: 2 | J10: TWSP7 | K10: Juggling | L10: 2 | M10: ASP7 | N10: Juggling | O10: 2
A11: BSP8 | B11: Water Filling Single | C11: 2 | D11: USP8 | E11: Biscut Eating | F11: 2 | G11: TSP8 | H11: Juggling | I11: 2 | J11: TWSP8 | K11: Crossbar Challenge | L11: 2 | M11: ASP8 | N11: Throw to stump | O11: 2
A12: BSP9 | B12: Biscut Eating | C12: 2 | D12: USP9 | E12: Juggling | F12: 2 | G12: TSP9 | H12: Throw to stump | I12: 2 | J12: TWSP9 | K12: Throw to stump | L12: 2 | M12: ASP9 | N12: Pot breaking | O12: 2
A13: BSP10 | B13: Sweet Pick-Up | C13: 2 | D13: USP10 | E13: Sweet Pick-Up | F13: 2 | G13: TSP10 | H13: Pot breaking | I13: 2 | J13: TWSP10 | K13: Pot breaking | L13: 2 | M13: ASP10 | N13: Pull Up | O13: 2
A14: BSP11 | B14: Balloon Breaking | C14: 2 | D14: USP11 | E14: Balloon Breaking | F14: 2 | G14: TSP11 | H14: Slow Race | I14: 2 | J14: TWSP11 | K14: Slow Race | L14: 2 | M14: ASP11 | N14: Arm Wrestling | O14: 2
A15: BSP12 | B15: Chair Play | C15: 2 | D15: USP12 | E15: Water Filling Group | F15: 2 | G15: TSP12 | H15: Water Filling Group | I15: 2 | J15: TWSP12 | K15: Pull Up | L15: 2 | M15: ASP12 | N15: Crossbar Challenge | O15: 2
A16: BSP13 | B16: Chair Play | C16: 2 | D16: USP13 | E16: Footsall | F16: 1 ( 4 persons ) | G16: TSP13 | H16: Arm wrestling | I16: 2 | J16: TWSP13 | K16: Water Filling Group | L16: 2 | M16: ASP13 | N16: Water Filling Group | O16: 2
A17: BSP14 | B17: Frog Jump | C17: 2 | G17: TSP14 | H17: Footsall | I17: 1(4 persons ) | J17: TWSP14 | K17: Throw to stump | L17: 2 | M17: ASP14 | N17: Biscuit eating | O17: 2
J18: TWSP15 | K18: Arm wrestling | L18: 2
J19: TWSP16 | K19: Crossbar Challenge | L19: 2

Sheet STAGE PROGRAM LIST
A1: STAGE PROGRAM LIST
A2: BIDĀYAH | D2: ʾŪLĀ | G2: THĀNIYAH | J2: THĀNAWIYYAH | M2: ʿĀLIYAH | P2: KULLIYYAH
A3: Code | B3: Programme Name | C3: No. of Participants | D3: Code | E3: Programme Name | F3: No. of Participants | G3: Code | H3: Programme Name | I3: No. of Participants | J3: Code | K3: Programme Name | L3: No. of Participants | M3: Code | N3: Programme Name | O3: No. of Participants | P3: Code | Q3: Programme Name | R3: No. of Participants
A4: BS1 | B4: QIRA'ATH | C4: 1 | D4: US1 | E4: QIRA'AH | F4: 2 | G4: TS1 | H4: HIFZ & QIRA'AH | I4: 2 | J4: TWS1 | K4: HIFZ & QIRA'AH | L4: 2 | M4: AS1 | N4: KHUTBAH | O4: 2 | P4: KS1 | Q4: QAWWALI URD | R4: 1*7
A5: BS2 | B5: HIFZ | C5: 1 | D5: US2 | E5: HIFZ | F5: 2 | G5: TS2 | H5: WA'Z | I5: 2 | J5: TWS2 | K5: WA'Z | L5: 2 | M5: AS2 | N5: WA'Z | O5: 2 | P5: KS2 | Q5: SAMA' | R5: 1*3
A6: BS3 | B6: ADHAN | C6: 1 | D6: US3 | E6: SONG MLM | F6: 2 | G6: TS3 | H6: BHAKTHI GANAM | I6: 2 | J6: TWS3 | K6: SONG URD | L6: 2 | M6: AS3 | N6: LECTURING ENG | O6: 2 | P6: KS3 | Q6: MEHFILE ISHQ | R6: 1*7
A7: BS4 | B7: SONG MLM | C7: 1 | D7: US4 | E7: SONG ENG | F7: 2 | G7: TS4 | H7: SONG ENG | I7: 2 | J7: TWS4 | K7: NASHID ARB | L7: 2 | M7: AS4 | N7: NASHEED ARB | O7: 2 | P7: KS4 | Q7: DEBATE ENGLISH | R7: 1*2
A8: BS5 | B8: SONG ARB | C8: 1 | D8: US5 | E8: SONG ARB | F8: 2 | G8: TS5 | H8: SONG ARB | I8: 2 | J8: TWS5 | K8: SPEECH URD | L8: 2 | M8: AS5 | N8: MAPPILAPPATTU | O8: 2 | P8: KS5 | Q8: DEBATE URDU | R8: 1*4
A9: BS6 | B9: SONG URD | C9: 1 | D9: US6 | E9: SONG URD | F9: 2 | G9: TS6 | H9: SONG URD | I9: 2 | J9: TWS6 | K9: SPEECH ARB | L9: 2 | M9: AS6 | N9: KAVIYARANG | O9: 2 | P9: KS6 | Q9: MUSHA'ARAH | R9: 1*5
A10: BS7 | B10: SPEECH MLM | C10: 1 | D10: US7 | E10: SPEECH MLM | F10: 2 | G10: TS7 | H10: SPEECH MLM | I10: 2 | J10: TWS7 | K10: TADRIS MLM | L10: 2 | M10: AS7 | N10: JUNCTION SPEECH MLM | O10: 2 | P10: KS7 | Q10: FATWA COUNCIL | R10: 1*7
A11: BS8 | B11: SPEECH ENG | C11: 1 | D11: US8 | E11: SPEECH ENG | F11: 2 | G11: TS8 | H11: SPEECH ENG | I11: 2 | J11: TWS8 | K11: INSPIRING TALK ENG | L11: 2 | M11: AS8 | N11: POLITICAL SATIRE MLM | O11: 2 | P11: KS8 | Q11: MUNAZARAH | R11: 1*3
A12: BS9 | B12: SPEECH ARB | C12: 1 | D12: US9 | E12: SPEECH ARB | F12: 2 | G12: TS9 | H12: SPEECH ARB | I12: 2 | J12: TWS9 | K12: GENERAL SPEECH | L12: 2 | M12: AS9 | N12: ACADEMIC TALK ENG | O12: 2 | P12: KS9 | Q12: BURDHA | R12: 1*6
A13: BS10 | B13: SPEECH URD | C13: 1 | D13: US10 | E13: SPEECH URD | F13: 2 | G13: TS10 | H13: SPEECH URD | I13: 2 | J13: TWS10 | K13: ANNOUNCEMENT | L13: 2 | M13: AS10 | N13: JOB INTERVIEW | O13: 2
A14: BS11 | B14: WA'Z | C14: 1 | D14: US11 | E14: WA'Z | F14: 2 | G14: TS11 | H14: PADHYAPARAYANAM | I14: 2 | J14: TWS11 | K14: GD MLM | L14: 2 | M14: AS11 | N14: DOCUMENTARY NARRATION ARB | O14: 2
A15: BS12 | B15: READING ENG | C15: 1 | D15: US12 | E15: PADHYAPARAYANAM | F15: 2 | G15: TS12 | H15: HISTORY TALK ENG | I15: 2 | J15: TWS12 | K15: PADAPATTU | L15: 2 | M15: AS12 | N15: NEWS WRITING & READING ARB | O15: 2
A16: BS13 | B16: READING ARB | C16: 1 | D16: US13 | E16: STORY NARRATION ENG | F16: 2 | G16: TS13 | H16: ORU NIMISHAM | I16: 2 | J16: TWS13 | K16: ALFIYYAH CONTEST | L16: 2 | M16: AS13 | N16: SIYASI THAQREER URD | O16: 2
A17: BS14 | B17: READING URD | C17: 1 | D17: US14 | E17: SPELLING BEE | F17: 2 | G17: TS14 | H17: NEWS WRITING AND READING MLM | I17: 2 | J17: TWS14 | K17: MULTILINGUAL QUIZ | L17: 2 | M17: AS14 | N17: REVERSE QUIZ | O17: 2
A18: BS15 | B18: KADHAKADHANAM | C18: 1 | D18: US15 | E18: MATHS TALENT | F18: 2 | G18: TS15 | H18: SPELLING BEE | I18: 2 | J18: TWS15 | K18: MATH TALENT | L18: 2 | M18: AS15 | N18: QUR'AN TALENT | O18: 2
A19: BS16 | B19: WORD FIGHT ENG | C19: 1 | D19: US16 | E19: GK QUIZ | F19: 2 | G19: TS16 | H19: GK QUIZ | I19: 2 | J19: TWS16 | K19: GK TALENT | L19: 2 | M19: AS16 | N19: AL FAQIH | O19: 2
A20: BS17 | B20: MATHS TALENT | C20: 2 | D20: US17 | E20: SWARF IQ | F20: 2 | G20: TS17 | H20: SCIENCE MASTER | I20: 2 | J20: TWS17 | K20: HADITH MUSABAQAH | L20: 2 | M20: AS17 | N20: PROUD MUSLIM | O20: 2
A21: BS18 | B21: CONVERSATION MLM | C21: 1*2 | D21: US18 | E21: GEO GIANT | F21: 2 | G21: TS18 | H21: GRAMMAR QUIZ | I21: 2 | J21: TWS18 | K21: TECH TANGLE | L21: 2 | M21: AS18 | N21: EXTEMPORE SPEECH ARB | O21: 2
A22: BS19 | B22: GROUP SONG | C22: 1*3 | D22: US19 | E22: WORD FIGHT ENG | F22: 2 | G22: TS19 | H22: MATHS TALENT | I22: 2 | J22: TWS19 | K22: FACE TO FACE ARB | L22: 1*2 | M22: AS19 | N22: COMMENTARY ARB | O22: 2
A23: BS20 | B23: SPEECH & SONG MLM | C23: 1*3 | D23: US20 | E23: MULAFAZAH ARB | F23: 2 | G23: TS20 | H23: SWARF IQ | I23: 2 | J23: TWS20 | K23: FACE TO FACE ENG | L23: 1*2 | M23: AS20 | N23: GAZAL | O23: 2
D24: US21 | E24: MULAFAZAH URD | F24: 2 | G24: TS21 | H24: PADAPPATTU | I24: 2 | J24: TWS21 | K24: MASHUP | L24: 1*4 | M24: AS21 | N24: LOGICAL REASONING | O24: 2
D25: US22 | E25: NJAN MALAYALI | F25: 2 | G25: TS22 | H25: SPEECH & SONG MLM | I25: 1*3 | J25: TWS22 | K25: TV NEWS REPORTING ENG | L25: 1*5 | M25: AS22 | N25: RJ TALK | O25: 2
D26: US23 | E26: CONVERSATION ENG | F26: 1*2 | G26: TS23 | H26: GROUP SONG | I26: 1*4 | M26: AS23 | N26: PADAPPATTU | O26: 2
D27: US24 | E27: CONVERSATION ARB | F27: 1*2 | M27: AS24 | N27: MOCK INTERVIEW ENG | O27: 2
D28: US25 | E28: CONVERSATION URD | F28: 1*2 | M28: AS25 | N28: VARSITY TALENT | O28: 2
D29: US26 | E29: GROUP SONG | F29: 1*3 | M29: AS26 | N29: MY PITCH | O29: 1*3

Sheet NON-STAGE PROGRAM LIST
A1: NON-STAGE PROGRAM LIST
A2: BIDĀYAH | D2: ʾŪLĀ | G2: THĀNIYAH | J2: THĀNAWIYYAH | M2: ʿĀLIYAH | P2: KULLIYYAH
A3: Code | B3: Programme Name | C3: No. of Participants | D3: Code | E3: Programme Name | F3: No. of Participants | G3: Code | H3: Programme Name | I3: No. of Participants | J3: Code | K3: Programme Name | L3: No. of Participants | M3: Code | N3: Programme Name | O3: No. of Participants | P3: Code | Q3: Programme Name | R3: No. of Participants
A4: BNS1 | B4: VOCABULARY | C4: 2 | D4: UNS1 | E4: SUDOKU | F4: 2 | G4: TNS1 | H4: SENTENCE TRANSLATION | I4: 2 | J4: TWNS1 | K4: TRANSLATION TRILINGUAL | L4: 2 | M4: ANS1 | N4: MR. TRANSLATOR | O4: 2 | P4: KNS1 | Q4: DIGITAL MAGAZINE | R4: -
A5: BNS2 | B5: GK QUIZ | C5: 2 | D5: UNS2 | E5: MEMORY TEST | F5: 2 | G5: TNS2 | H5: ACRYLIC PAINTING | I5: 2 | J5: TWNS2 | K5: SCIENCE MASTER | L5: 2 | M5: ANS2 | N5: AL 'ARABI | O5: 2 | P5: KNS2 | Q5: PHOTO ESSAY | R5: -
A6: BNS3 | B6: MEMORY TEST | C6: 2 | D6: UNS3 | E6: VOCABULARY | F6: 2 | G6: TNS3 | H6: ESSAY MLM | I6: 2 | J6: TWNS3 | K6: MANIPULATION POSTER | L6: 2 | M6: ANS3 | N6: ALLAME URDU | O6: 2 | P6: KNS3 | Q6: REEL MAKING | R6: -
A7: BNS4 | B7: POEM WRITING MLM | C7: 2 | D7: UNS4 | E7: SCIENCE MASTER | F7: 2 | G7: TNS4 | H7: ESSAY ENG | I7: 2 | J7: TWNS4 | K7: DIGITAL TYPOGRAPHY MLM | L7: 2 | M7: ANS4 | N7: MR. ENGLISH | O7: 2 | P7: KNS4 | Q7: AI VIDEO GENERATION | R7: -
A8: BNS5 | B8: PICTURE STORY MLM | C8: 2 | D8: UNS5 | E8: HINDI VIDUAN | F8: 2 | G8: TNS5 | H8: ESSAY ARB | I8: 2 | J8: TWNS5 | K8: ESSAY MLM | L8: 2 | M8: ANS5 | N8: MR. ESPAÑOL | O8: 2 | P8: KNS5 | Q8: WALL PAINTING | R8: -
A9: BNS6 | B9: CAPTION MAKING | C9: 2 | D9: UNS6 | E9: ESSAY MLM | F9: 2 | G9: TNS6 | H9: ESSAY URD | I9: 2 | J9: TWNS6 | K9: ESSAY ENG | L9: 2 | M9: ANS6 | N9: ESSAY MLM | O9: 2 | P9: KNS6 | Q9: THEME SUBMISSION | R9: -
A10: BNS7 | B10: DICTIONARY MAKING ARB | C10: 2 | D10: UNS7 | E10: LETTER WRITING ENG | F10: 2 | G10: TNS7 | H10: ESSAY HINDI | I10: 2 | J10: TWNS7 | K10: ESSAY ARB | L10: 2 | M10: ANS7 | N10: ESSAY ARB | O10: 2 | P10: KNS7 | Q10: MOTION CANVAS | R10: -
A11: BNS8 | B11: MULTILINGUAL HANDWRITING | C11: 3 | D11: UNS8 | E11: POEM WRITING MLM | F11: 2 | G11: TNS8 | H11: POEM MLM | I11: 2 | J11: TWNS8 | K11: ESSAY URD | L11: 2 | M11: ANS8 | N11: ESSAY URD | O11: 2 | P11: KNS8 | Q11: EXPOSITORY DOCUMENTARY | R11: -
A12: BNS9 | B12: PENCIL DRAWING | C12: 2 | D12: UNS9 | E12: POEM WRITING ENG | F12: 2 | G12: TNS9 | H12: POEM ENG | I12: 2 | J12: TWNS9 | K12: POEM ARB | L12: 2 | M12: ANS9 | N12: ACADEMIC ESSAY ENG | O12: 2 | P12: KNS9 | Q12: HACKATHON | R12: -
A13: BNS10 | B13: PIXEL PALETTE | C13: 2 | D13: UNS10 | E13: SHORT STORY MLM | F13: 2 | G13: TNS10 | H13: POEM ARB | I13: 2 | J13: TWNS10 | K13: POEM URD | L13: 2 | M13: ANS10 | N13: POEM MLM | O13: 2 | P13: KNS10 | Q13: VLOG MAKING | R13: -
A14: BNS11 | B14: TYPING MASTER ENG | C14: 2 | D14: UNS11 | E14: STORY COMPLETION ENG | F14: 2 | G14: TNS11 | H14: POEM URD | I14: 2 | J14: TWNS11 | K14: PROS TO POETRY MLM | L14: 2 | M14: ANS11 | N14: POEM ENG | O14: 2
A15: BNS12 | B15: MS WORD | C15: 2 | D15: UNS12 | E15: STORY COMPLETION ARB | F15: 2 | G15: TNS12 | H15: SHORT STORY MLM | I15: 2 | J15: TWNS12 | K15: PROS TO POETRY ENG | L15: 2 | M15: ANS12 | N15: POEM ARB | O15: 2
A16: BNS13 | B16: ESSAY WRITING MLM | C16: 2 | D16: UNS13 | E16: STORY COMPLETION URD | F16: 2 | G16: TNS13 | H16: SHORT STORY ENG | I16: 2 | J16: TWNS13 | K16: MR CRICTIC MLM | L16: 2 | M16: ANS13 | N16: POEM URD | O16: 2
A17: BNS14 | B17: SUDOKU | C17: 2 | D17: UNS14 | E17: IMAGE ELABORATION MLM | F17: 2 | G17: TNS14 | H17: SHORT STORY ARB | I17: 2 | J17: TWNS14 | K17: NEWS WRITING ENG | L17: 2 | M17: ANS14 | N17: TARJUMAN-E-SADA | O17: 2
A18: BNS15 | B18: ORIGAMI | C18: 2 | D18: UNS15 | E18: WATER PAINTING | F18: 2 | G18: TNS15 | H18: SHORT STORY URD | I18: 2 | J18: TWNS15 | K18: NEWS WRITING ARB | L18: 2 | M18: ANS15 | N18: SHORT STORY MLM | O18: 2
A19: BNS16 | B19: JIGSAW PUZZLE | C19: 2 | D19: UNS16 | E19: CARTOON | F19: 2 | G19: TNS16 | H19: TEXT TORNADO | I19: 2 | J19: TWNS16 | K19: NEWS WRITING URD | L19: 2 | M19: ANS16 | N19: SHORT STORY ENG | O19: 2
A20: BNS17 | B20: WATER PAINTING | C20: 2 | D20: UNS17 | E20: POSTER DESIGNING | F20: 2 | G20: TNS17 | H20: CARTOON | I20: 2 | J20: TWNS17 | K20: SHORT STORY MLM | L20: 2 | M20: ANS17 | N20: SHORT STORY ARB | O20: 2
D21: UNS18 | E21: TYPING BI-LINGUAL | F21: 2 | G21: TNS18 | H21: DICTIONARY MAKING HINDI | I21: 2 | J21: TWNS18 | K21: SHORT STORY ENG | L21: 2 | M21: ANS18 | N21: SHORT STORY URD | O21: 2
D22: UNS19 | E22: POWERPOINT CREATION | F22: 2 | G22: TNS19 | H22: EXCEL MASTER | I22: 2 | J22: TWNS19 | K22: SHORT STORY ARB | L22: 2 | M22: ANS19 | N22: SCREENPLAY WRITING MLM | O22: 2
D23: UNS20 | E23: TABLOID MLM | F23: 1*5 | G23: TNS20 | H23: POSTER DESIGNING | I23: 2 | J23: TWNS20 | K23: SHORT STORY URD | L23: 2 | M23: ANS20 | N23: ABSTRACT WRITING ENG | O23: 2
G24: TNS21 | H24: VIDEO EDITING | I24: 2 | J24: TWNS21 | K24: TWEETING | L24: 2 | M24: ANS21 | N24: COPYWRITING MLM | O24: 2
G25: TNS22 | H25: IMAGE ELABORATION ENG | I25: 2 | J25: TWNS22 | K25: CALLIGRAPHY | L25: 2 | M25: ANS22 | N25: FEATURE WRITING MLM | O25: 2
G26: TNS23 | H26: INSTANT CHILDREN'S MAGAZINE MLM | I26: 1*5 | J26: TWNS23 | K26: CARTOON | L26: 2 | M26: ANS23 | N26: BAYAN ART | O26: 2
G27: TNS24 | H27: INSTANT NEWSPAPER MLM | I27: 1*5 | J27: TWNS24 | K27: CRYPTIC CROSSWORD | L27: 2 | M27: ANS24 | N27: PROMPT ENGINEERING | O27: 2
J28: TWNS25 | K28: PRODUCT PHOTOGRAPHY | L28: 2 | M28: ANS25 | N28: UI DESIGNING | O28: 2
J29: TWNS26 | K29: WEB DESIGNING | L29: 2 | M29: ANS26 | N29: CODE CRAFT | O29: 2
J30: TWNS27 | K30: CANDID PHOTOGRAPHY | L30: 2 | M30: ANS27 | N30: HAIKU POEM | O30: 2
J31: TWNS28 | K31: INSTANT MAGAZINE ENG | L31: 1*5 | M31: ANS28 | N31: MANUSCRIPT READING | O31: 2
M32: ANS29 | N32: CANVAS PAINTING | O32: 2
M33: ANS30 | N33: PACKAGE DESIGNING | O33: 2
M34: ANS31 | N34: ADVENTURE PHOTOGRAPHY | O34: 2
M35: ANS32 | N35: DIGITAL TABLOID ARB | O35: 1*5
M36: ANS33 | N36: BROCHURE DESIGNNG | O36: 1*4

Sheet MASTER LIST
B1: NAME | C1: CLASS | D1: CATEGORY | E1: TEAM | F1: STATUS | G1: Non-Stage Count | H1: ST Count | I1: Sports Count | J1: Individual Count | K1: Group Count | L1: Total Count | M1: Bylaw Status | N1: REG 1 | O1: REG 2 | P1: REG 3 | Q1: REG 4 | R1: REG 5 | S1: REG 6 | T1: REG 7 | U1: REG 8 | V1: REG 9 | W1: REG 10 | X1: REG 11 | Y1: REG 12 | Z1: REG 13 | AA1: REG 14 | AB1: REG 15 | AC1: REGISTERED PROGRAMS
A2: 67 | B2: MUHAMMED ABDUL SALEEM K | C2: 10 | D2: ʿĀLIYAH | E2: TEAM C | F2: Active | G2: =SUMPRODUCT(COUNTIFS(PROGRAM_DIRECTORY!$A$2:$A$334, $N2:$AB2, PROGRAM_DIRECTORY!$D$2:$D$334, "Non-Stage", PROGRAM_DIRECTORY!$E$2:$E$334, "Individual")) -> 0 | H2: =SUMPRODUCT(COUNTIFS(PROGRAM_DIRECTORY!$A$2:$A$334, $N2:$AB2, PROGRAM_DIRECTORY!$D$2:$D$334, "Stage", PROGRAM_DIRECTORY!$E$2:$E$334, "Individual")) -> 0 | I2: =SUMPRODUCT(COUNTIFS(PROGRAM_DIRECTORY!$A$2:$A$334, $N2:$AB2, PROGRAM_DIRECTORY!$D$2:$D$334, "Sports")) -> 0 | J2: =SUMPRODUCT(COUNTIFS(PROGRAM_DIRECTORY!$A$2:$A$334, $N2:$AB2, PROGRAM_DIRECTORY!$E$2:$E$334, "Individual")) -> 0 | K2: =SUMPRODUCT(COUNTIFS(PROGRAM_DIRECTORY!$A$2:$A$334, $N2:$AB2, PROGRAM_DIRECTORY!$E$2:$E$334, "Group")) -> 0 | L2: =COUNTIF($N2:$AB2, "<>") -> 0 | M2: =IF($F2<>"Active", "Inactive Student", IF($J2>IF(OR($D2="BIDĀYAH", $D2="BIDAYAH"), 12, IF(OR($D2="THĀNAWIYYAH", $D2="THANAWIYYAH"), 10, 9)), "Individual Quota Exceeded", IF($G2>IF(OR($D2="BIDĀYAH", $D2="BIDAYAH"), 8, IF(OR($D2="THĀNAWIYYAH", $D2="THANAWIYYAH"), 6, 5)), "Non-Stage Quota Exceeded", IF($H2>4, "Stage Quota Exceeded", IF(AND($H2=0, $G2=0), "Min 1 Required (Stage & Non-Stage)", IF($H2=0, "Min 1 Required (Stage)", IF($G2=0, "Min 1 Required (Non-Stage)", "Compliant"))))))) -> Min 1 Required (Stage & Non-Stage) | AC2: =TEXTJOIN(", ", TRUE, $N2:$AB2)
A3: 68 | B3: MUHAMMED SALIM K | C3: 10 | D3: ʿĀLIYAH | E3: TEAM A | F3: Active | G3: =SUMPRODUCT(COUNTIFS(PROGRAM_DIRECTORY!$A$2:$A$334, $N3:$AB3, PROGRAM_DIRECTORY!$D$2:$D$334, "Non-Stage", PROGRAM_DIRECTORY!$E$2:$E$334, "Individual")) -> 0 | H3: =SUMPRODUCT(COUNTIFS(PROGRAM_DIRECTORY!$A$2:$A$334, $N3:$AB3, PROGRAM_DIRECTORY!$D$2:$D$334, "Stage", PROGRAM_DIRECTORY!$E$2:$E$334, "Individual")) -> 0 | I3: =SUMPRODUCT(COUNTIFS(PROGRAM_DIRECTORY!$A$2:$A$334, $N3:$AB3, PROGRAM_DIRECTORY!$D$2:$D$334, "Sports")) -> 0 | J3: =SUMPRODUCT(COUNTIFS(PROGRAM_DIRECTORY!$A$2:$A$334, $N3:$AB3, PROGRAM_DIRECTORY!$E$2:$E$334, "Individual")) -> 0 | K3: =SUMPRODUCT(COUNTIFS(PROGRAM_DIRECTORY!$A$2:$A$334, $N3:$AB3, PROGRAM_DIRECTORY!$E$2:$E$334, "Group")) -> 0 | L3: =COUNTIF($N3:$AB3, "<>") -> 0 | M3: =IF($F3<>"Active", "Inactive Student", IF($J3>IF(OR($D3="BIDĀYAH", $D3="BIDAYAH"), 12, IF(OR($D3="THĀNAWIYYAH", $D3="THANAWIYYAH"), 10, 9)), "Individual Quota Exceeded", IF($G3>IF(OR($D3="BIDĀYAH", $D3="BIDAYAH"), 8, IF(OR($D3="THĀNAWIYYAH", $D3="THANAWIYYAH"), 6, 5)), "Non-Stage Quota Exceeded", IF($H3>4, "Stage Quota Exceeded", IF(AND($H3=0, $G3=0), "Min 1 Required (Stage & Non-Stage)", IF($H3=0, "Min 1 Required (Stage)", IF($G3=0, "Min 1 Required (Non-Stage)", "Compliant"))))))) -> Min 1 Required (Stage & Non-Stage) | AC3: =TEXTJOIN(", ", TRUE, $N3:$AB3)
A4: 357 | B4: MUHAMMED ANSAR PK | C4: 10 | D4: ʿĀLIYAH | E4: TEAM B | F4: Active | G4: =SUMPRODUCT(COUNTIFS(PROGRAM_DIRECTORY!$A$2:$A$334, $N4:$AB4, PROGRAM_DIRECTORY!$D$2:$D$334, "Non-Stage", PROGRAM_DIRECTORY!$E$2:$E$334, "Individual")) -> 0 | H4: =SUMPRODUCT(COUNTIFS(PROGRAM_DIRECTORY!$A$2:$A$334, $N4:$AB4, PROGRAM_DIRECTORY!$D$2:$D$334, "Stage", PROGRAM_DIRECTORY!$E$2:$E$334, "Individual")) -> 0 | I4: =SUMPRODUCT(COUNTIFS(PROGRAM_DIRECTORY!$A$2:$A$334, $N4:$AB4, PROGRAM_DIRECTORY!$D$2:$D$334, "Sports")) -> 0 | J4: =SUMPRODUCT(COUNTIFS(PROGRAM_DIRECTORY!$A$2:$A$334, $N4:$AB4, PROGRAM_DIRECTORY!$E$2:$E$334, "Individual")) -> 0 | K4: =SUMPRODUCT(COUNTIFS(PROGRAM_DIRECTORY!$A$2:$A$334, $N4:$AB4, PROGRAM_DIRECTORY!$E$2:$E$334, "Group")) -> 0 | L4: =COUNTIF($N4:$AB4, "<>") -> 0 | M4: =IF($F4<>"Active", "Inactive Student", IF($J4>IF(OR($D4="BIDĀYAH", $D4="BIDAYAH"), 12, IF(OR($D4="THĀNAWIYYAH", $D4="THANAWIYYAH"), 10, 9)), "Individual Quota Exceeded", IF($G4>IF(OR($D4="BIDĀYAH", $D4="BIDAYAH"), 8, IF(OR($D4="THĀNAWIYYAH", $D4="THANAWIYYAH"), 6, 5)), "Non-Stage Quota Exceeded", IF($H4>4, "Stage Quota Exceeded", IF(AND($H4=0, $G4=0), "Min 1 Required (Stage & Non-Stage)", IF($H4=0, "Min 1 Required (Stage)", IF($G4=0, "Min 1 Required (Non-Stage)", "Compliant"))))))) -> Min 1 Required (Stage & Non-Stage) | AC4: =TEXTJOIN(", ", TRUE, $N4:$AB4)
A5: 71 | B5: AAKHIL MUHAMMED K | C5: 10 | D5: ʿĀLIYAH | E5: TEAM A | F5: Active | G5: =SUMPRODUCT(COUNTIFS(PROGRAM_DIRECTORY!$A$2:$A$334, $N5:$AB5, PROGRAM_DIRECTORY!$D$2:$D$334, "Non-Stage", PROGRAM_DIRECTORY!$E$2:$E$334, "Individual")) -> 0 | H5: =SUMPRODUCT(COUNTIFS(PROGRAM_DIRECTORY!$A$2:$A$334, $N5:$AB5, PROGRAM_DIRECTORY!$D$2:$D$334, "Stage", PROGRAM_DIRECTORY!$E$2:$E$334, "Individual")) -> 0 | I5: =SUMPRODUCT(COUNTIFS(PROGRAM_DIRECTORY!$A$2:$A$334, $N5:$AB5, PROGRAM_DIRECTORY!$D$2:$D$334, "Sports")) -> 0 | J5: =SUMPRODUCT(COUNTIFS(PROGRAM_DIRECTORY!$A$2:$A$334, $N5:$AB5, PROGRAM_DIRECTORY!$E$2:$E$334, "Individual")) -> 0 | K5: =SUMPRODUCT(COUNTIFS(PROGRAM_DIRECTORY!$A$2:$A$334, $N5:$AB5, PROGRAM_DIRECTORY!$E$2:$E$334, "Group")) -> 0 | L5: =COUNTIF($N5:$AB5, "<>") -> 0 | M5: =IF($F5<>"Active", "Inactive Student", IF($J5>IF(OR($D5="BIDĀYAH", $D5="BIDAYAH"), 12, IF(OR($D5="THĀNAWIYYAH", $D5="THANAWIYYAH"), 10, 9)), "Individual Quota Exceeded", IF($G5>IF(OR($D5="BIDĀYAH", $D5="BIDAYAH"), 8, IF(OR($D5="THĀNAWIYYAH", $D5="THANAWIYYAH"), 6, 5)), "Non-Stage Quota Exceeded", IF($H5>4, "Stage Quota Exceeded", IF(AND($H5=0, $G5=0), "Min 1 Required (Stage & Non-Stage)", IF($H5=0, "Min 1 Required (Stage)", IF($G5=0, "Min 1 Required (Non-Stage)", "Compliant"))))))) -> Min 1 Required (Stage & Non-Stage) | AC5: =TEXTJOIN(", ", TRUE, $N5:$AB5)
A6: 393 | B6: MUHAMMED SALMAN OK | C6: 10 | D6: ʿĀLIYAH | E6: TEAM D | F6: Active | G6: =SUMPRODUCT(COUNTIFS(PROGRAM_DIRECTORY!$A$2:$A$334, $N6:$AB6, PROGRAM_DIRECTORY!$D$2:$D$334, "Non-Stage", PROGRAM_DIRECTORY!$E$2:$E$334, "Individual")) -> 0 | H6: =SUMPRODUCT(COUNTIFS(PROGRAM_DIRECTORY!$A$2:$A$334, $N6:$AB6, PROGRAM_DIRECTORY!$D$2:$D$334, "Stage", PROGRAM_DIRECTORY!$E$2:$E$334, "Individual")) -> 0 | I6: =SUMPRODUCT(COUNTIFS(PROGRAM_DIRECTORY!$A$2:$A$334, $N6:$AB6, PROGRAM_DIRECTORY!$D$2:$D$334, "Sports")) -> 0 | J6: =SUMPRODUCT(COUNTIFS(PROGRAM_DIRECTORY!$A$2:$A$334, $N6:$AB6, PROGRAM_DIRECTORY!$E$2:$E$334, "Individual")) -> 0 | K6: =SUMPRODUCT(COUNTIFS(PROGRAM_DIRECTORY!$A$2:$A$334, $N6:$AB6, PROGRAM_DIRECTORY!$E$2:$E$334, "Group")) -> 0 | L6: =COUNTIF($N6:$AB6, "<>") -> 0 | M6: =IF($F6<>"Active", "Inactive Student", IF($J6>IF(OR($D6="BIDĀYAH", $D6="BIDAYAH"), 12, IF(OR($D6="THĀNAWIYYAH", $D6="THANAWIYYAH"), 10, 9)), "Individual Quota Exceeded", IF($G6>IF(OR($D6="BIDĀYAH", $D6="BIDAYAH"), 8, IF(OR($D6="THĀNAWIYYAH", $D6="THANAWIYYAH"), 6, 5)), "Non-Stage Quota Exceeded", IF($H6>4, "Stage Quota Exceeded", IF(AND($H6=0, $G6=0), "Min 1 Required (Stage & Non-Stage)", IF($H6=0, "Min 1 Required (Stage)", IF($G6=0, "Min 1 Required (Non-Stage)", "Compliant"))))))) -> Min 1 Required (Stage & Non-Stage) | AC6: =TEXTJOIN(", ", TRUE, $N6:$AB6)
A7: 78 | B7: MUHAMMED FARHAN | C7: 10 | D7: ʿĀLIYAH | E7: TEAM B | F7: Active | G7: =SUMPRODUCT(COUNTIFS(PROGRAM_DIRECTORY!$A$2:$A$334, $N7:$AB7, PROGRAM_DIRECTORY!$D$2:$D$334, "Non-Stage", PROGRAM_DIRECTORY!$E$2:$E$334, "Individual")) -> 0 | H7: =SUMPRODUCT(COUNTIFS(PROGRAM_DIRECTORY!$A$2:$A$334, $N7:$AB7, PROGRAM_DIRECTORY!$D$2:$D$334, "Stage", PROGRAM_DIRECTORY!$E$2:$E$334, "Individual")) -> 0 | I7: =SUMPRODUCT(COUNTIFS(PROGRAM_DIRECTORY!$A$2:$A$334, $N7:$AB7, PROGRAM_DIRECTORY!$D$2:$D$334, "Sports")) -> 0 | J7: =SUMPRODUCT(COUNTIFS(PROGRAM_DIRECTORY!$A$2:$A$334, $N7:$AB7, PROGRAM_DIRECTORY!$E$2:$E$334, "Individual")) -> 0 | K7: =SUMPRODUCT(COUNTIFS(PROGRAM_DIRECTORY!$A$2:$A$334, $N7:$AB7, PROGRAM_DIRECTORY!$E$2:$E$334, "Group")) -> 0 | L7: =COUNTIF($N7:$AB7, "<>") -> 0 | M7: =IF($F7<>"Active", "Inactive Student", IF($J7>IF(OR($D7="BIDĀYAH", $D7="BIDAYAH"), 12, IF(OR($D7="THĀNAWIYYAH", $D7="THANAWIYYAH"), 10, 9)), "Individual Quota Exceeded", IF($G7>IF(OR($D7="BIDĀYAH", $D7="BIDAYAH"), 8, IF(OR($D7="THĀNAWIYYAH", $D7="THANAWIYYAH"), 6, 5)), "Non-Stage Quota Exceeded", IF($H7>4, "Stage Quota Exceeded", IF(AND($H7=0, $G7=0), "Min 1 Required (Stage & Non-Stage)", IF($H7=0, "Min 1 Required (Stage)", IF($G7=0, "Min 1 Required (Non-Stage)", "Compliant"))))))) -> Min 1 Required (Stage & Non-Stage) | AC7: =TEXTJOIN(", ", TRUE, $N7:$AB7)
A8: 356 | B8: SHIHAD TK | C8: 10 | D8: ʿĀLIYAH | E8: TEAM C | F8: Active | G8: =SUMPRODUCT(COUNTIFS(PROGRAM_DIRECTORY!$A$2:$A$334, $N8:$AB8, PROGRAM_DIRECTORY!$D$2:$D$334, "Non-Stage", PROGRAM_DIRECTORY!$E$2:$E$334, "Individual")) -> 0 | H8: =SUMPRODUCT(COUNTIFS(PROGRAM_DIRECTORY!$A$2:$A$334, $N8:$AB8, PROGRAM_DIRECTORY!$D$2:$D$334, "Stage", PROGRAM_DIRECTORY!$E$2:$E$334, "Individual")) -> 0 | I8: =SUMPRODUCT(COUNTIFS(PROGRAM_DIRECTORY!$A$2:$A$334, $N8:$AB8, PROGRAM_DIRECTORY!$D$2:$D$334, "Sports")) -> 0 | J8: =SUMPRODUCT(COUNTIFS(PROGRAM_DIRECTORY!$A$2:$A$334, $N8:$AB8, PROGRAM_DIRECTORY!$E$2:$E$334, "Individual")) -> 0 | K8: =SUMPRODUCT(COUNTIFS(PROGRAM_DIRECTORY!$A$2:$A$334, $N8:$AB8, PROGRAM_DIRECTORY!$E$2:$E$334, "Group")) -> 0 | L8: =COUNTIF($N8:$AB8, "<>") -> 0 | M8: =IF($F8<>"Active", "Inactive Student", IF($J8>IF(OR($D8="BIDĀYAH", $D8="BIDAYAH"), 12, IF(OR($D8="THĀNAWIYYAH", $D8="THANAWIYYAH"), 10, 9)), "Individual Quota Exceeded", IF($G8>IF(OR($D8="BIDĀYAH", $D8="BIDAYAH"), 8, IF(OR($D8="THĀNAWIYYAH", $D8="THANAWIYYAH"), 6, 5)), "Non-Stage Quota Exceeded", IF($H8>4, "Stage Quota Exceeded", IF(AND($H8=0, $G8=0), "Min 1 Required (Stage & Non-Stage)", IF($H8=0, "Min 1 Required (Stage)", IF($G8=0, "Min 1 Required (Non-Stage)", "Compliant"))))))) -> Min 1 Required (Stage & Non-Stage) | AC8: =TEXTJOIN(", ", TRUE, $N8:$AB8)
A9: 354 | B9: MUHAMMED ALTHAF K | C9: 10 | D9: ʿĀLIYAH | E9: TEAM D | F9: Active | G9: =SUMPRODUCT(COUNTIFS(PROGRAM_DIRECTORY!$A$2:$A$334, $N9:$AB9, PROGRAM_DIRECTORY!$D$2:$D$334, "Non-Stage", PROGRAM_DIRECTORY!$E$2:$E$334, "Individual")) -> 0 | H9: =SUMPRODUCT(COUNTIFS(PROGRAM_DIRECTORY!$A$2:$A$334, $N9:$AB9, PROGRAM_DIRECTORY!$D$2:$D$334, "Stage", PROGRAM_DIRECTORY!$E$2:$E$334, "Individual")) -> 0 | I9: =SUMPRODUCT(COUNTIFS(PROGRAM_DIRECTORY!$A$2:$A$334, $N9:$AB9, PROGRAM_DIRECTORY!$D$2:$D$334, "Sports")) -> 0 | J9: =SUMPRODUCT(COUNTIFS(PROGRAM_DIRECTORY!$A$2:$A$334, $N9:$AB9, PROGRAM_DIRECTORY!$E$2:$E$334, "Individual")) -> 0 | K9: =SUMPRODUCT(COUNTIFS(PROGRAM_DIRECTORY!$A$2:$A$334, $N9:$AB9, PROGRAM_DIRECTORY!$E$2:$E$334, "Group")) -> 0 | L9: =COUNTIF($N9:$AB9, "<>") -> 0 | M9: =IF($F9<>"Active", "Inactive Student", IF($J9>IF(OR($D9="BIDĀYAH", $D9="BIDAYAH"), 12, IF(OR($D9="THĀNAWIYYAH", $D9="THANAWIYYAH"), 10, 9)), "Individual Quota Exceeded", IF($G9>IF(OR($D9="BIDĀYAH", $D9="BIDAYAH"), 8, IF(OR($D9="THĀNAWIYYAH", $D9="THANAWIYYAH"), 6, 5)), "Non-Stage Quota Exceeded", IF($H9>4, "Stage Quota Exceeded", IF(AND($H9=0, $G9=0), "Min 1 Required (Stage & Non-Stage)", IF($H9=0, "Min 1 Required (Stage)", IF($G9=0, "Min 1 Required (Non-Stage)", "Compliant"))))))) -> Min 1 Required (Stage & Non-Stage) | AC9: =TEXTJOIN(", ", TRUE, $N9:$AB9)
A10: 56 | B10: MUHAMMED SAHAL KC | C10: 10 | D10: ʿĀLIYAH | E10: TEAM D | F10: Active | G10: =SUMPRODUCT(COUNTIFS(PROGRAM_DIRECTORY!$A$2:$A$334, $N10:$AB10, PROGRAM_DIRECTORY!$D$2:$D$334, "Non-Stage", PROGRAM_DIRECTORY!$E$2:$E$334, "Individual")) -> 0 | H10: =SUMPRODUCT(COUNTIFS(PROGRAM_DIRECTORY!$A$2:$A$334, $N10:$AB10, PROGRAM_DIRECTORY!$D$2:$D$334, "Stage", PROGRAM_DIRECTORY!$E$2:$E$334, "Individual")) -> 0 | I10: =SUMPRODUCT(COUNTIFS(PROGRAM_DIRECTORY!$A$2:$A$334, $N10:$AB10, PROGRAM_DIRECTORY!$D$2:$D$334, "Sports")) -> 0 | J10: =SUMPRODUCT(COUNTIFS(PROGRAM_DIRECTORY!$A$2:$A$334, $N10:$AB10, PROGRAM_DIRECTORY!$E$2:$E$334, "Individual")) -> 0 | K10: =SUMPRODUCT(COUNTIFS(PROGRAM_DIRECTORY!$A$2:$A$334, $N10:$AB10, PROGRAM_DIRECTORY!$E$2:$E$334, "Group")) -> 0 | L10: =COUNTIF($N10:$AB10, "<>") -> 0 | M10: =IF($F10<>"Active", "Inactive Student", IF($J10>IF(OR($D10="BIDĀYAH", $D10="BIDAYAH"), 12, IF(OR($D10="THĀNAWIYYAH", $D10="THANAWIYYAH"), 10, 9)), "Individual Quota Exceeded", IF($G10>IF(OR($D10="BIDĀYAH", $D10="BIDAYAH"), 8, IF(OR($D10="THĀNAWIYYAH", $D10="THANAWIYYAH"), 6, 5)), "Non-Stage Quota Exceeded", IF($H10>4, "Stage Quota Exceeded", IF(AND($H10=0, $G10=0), "Min 1 Required (Stage & Non-Stage)", IF($H10=0, "Min 1 Required (Stage)", IF($G10=0, "Min 1 Required (Non-Stage)", "Compliant"))))))) -> Min 1 Required (Stage & Non-Stage) | AC10: =TEXTJOIN(", ", TRUE, $N10:$AB10)
A11: 64 | B11: UNAIS K | C11: 10 | D11: ʿĀLIYAH | E11: TEAM A | F11: Active | G11: =SUMPRODUCT(COUNTIFS(PROGRAM_DIRECTORY!$A$2:$A$334, $N11:$AB11, PROGRAM_DIRECTORY!$D$2:$D$334, "Non-Stage", PROGRAM_DIRECTORY!$E$2:$E$334, "Individual")) -> 0 | H11: =SUMPRODUCT(COUNTIFS(PROGRAM_DIRECTORY!$A$2:$A$334, $N11:$AB11, PROGRAM_DIRECTORY!$D$2:$D$334, "Stage", PROGRAM_DIRECTORY!$E$2:$E$334, "Individual")) -> 0 | I11: =SUMPRODUCT(COUNTIFS(PROGRAM_DIRECTORY!$A$2:$A$334, $N11:$AB11, PROGRAM_DIRECTORY!$D$2:$D$334, "Sports")) -> 0 | J11: =SUMPRODUCT(COUNTIFS(PROGRAM_DIRECTORY!$A$2:$A$334, $N11:$AB11, PROGRAM_DIRECTORY!$E$2:$E$334, "Individual")) -> 0 | K11: =SUMPRODUCT(COUNTIFS(PROGRAM_DIRECTORY!$A$2:$A$334, $N11:$AB11, PROGRAM_DIRECTORY!$E$2:$E$334, "Group")) -> 0 | L11: =COUNTIF($N11:$AB11, "<>") -> 0 | M11: =IF($F11<>"Active", "Inactive Student", IF($J11>IF(OR($D11="BIDĀYAH", $D11="BIDAYAH"), 12, IF(OR($D11="THĀNAWIYYAH", $D11="THANAWIYYAH"), 10, 9)), "Individual Quota Exceeded", IF($G11>IF(OR($D11="BIDĀYAH", $D11="BIDAYAH"), 8, IF(OR($D11="THĀNAWIYYAH", $D11="THANAWIYYAH"), 6, 5)), "Non-Stage Quota Exceeded", IF($H11>4, "Stage Quota Exceeded", IF(AND($H11=0, $G11=0), "Min 1 Required (Stage & Non-Stage)", IF($H11=0, "Min 1 Required (Stage)", IF($G11=0, "Min 1 Required (Non-Stage)", "Compliant"))))))) -> Min 1 Required (Stage & Non-Stage) | AC11: =TEXTJOIN(", ", TRUE, $N11:$AB11)
A12: 45 | B12: AKHEEL NASIM | C12: 10 | D12: ʿĀLIYAH | E12: TEAM D | F12: Active | G12: =SUMPRODUCT(COUNTIFS(PROGRAM_DIRECTORY!$A$2:$A$334, $N12:$AB12, PROGRAM_DIRECTORY!$D$2:$D$334, "Non-Stage", PROGRAM_DIRECTORY!$E$2:$E$334, "Individual")) -> 0 | H12: =SUMPRODUCT(COUNTIFS(PROGRAM_DIRECTORY!$A$2:$A$334, $N12:$AB12, PROGRAM_DIRECTORY!$D$2:$D$334, "Stage", PROGRAM_DIRECTORY!$E$2:$E$334, "Individual")) -> 0 | I12: =SUMPRODUCT(COUNTIFS(PROGRAM_DIRECTORY!$A$2:$A$334, $N12:$AB12, PROGRAM_DIRECTORY!$D$2:$D$334, "Sports")) -> 0 | J12: =SUMPRODUCT(COUNTIFS(PROGRAM_DIRECTORY!$A$2:$A$334, $N12:$AB12, PROGRAM_DIRECTORY!$E$2:$E$334, "Individual")) -> 0 | K12: =SUMPRODUCT(COUNTIFS(PROGRAM_DIRECTORY!$A$2:$A$334, $N12:$AB12, PROGRAM_DIRECTORY!$E$2:$E$334, "Group")) -> 0 | L12: =COUNTIF($N12:$AB12, "<>") -> 0 | M12: =IF($F12<>"Active", "Inactive Student", IF($J12>IF(OR($D12="BIDĀYAH", $D12="BIDAYAH"), 12, IF(OR($D12="THĀNAWIYYAH", $D12="THANAWIYYAH"), 10, 9)), "Individual Quota Exceeded", IF($G12>IF(OR($D12="BIDĀYAH", $D12="BIDAYAH"), 8, IF(OR($D12="THĀNAWIYYAH", $D12="THANAWIYYAH"), 6, 5)), "Non-Stage Quota Exceeded", IF($H12>4, "Stage Quota Exceeded", IF(AND($H12=0, $G12=0), "Min 1 Required (Stage & Non-Stage)", IF($H12=0, "Min 1 Required (Stage)", IF($G12=0, "Min 1 Required (Non-Stage)", "Compliant"))))))) -> Min 1 Required (Stage & Non-Stage) | AC12: =TEXTJOIN(", ", TRUE, $N12:$AB12)
A13: 66 | B13: MUHAMMED SAFEER MP | C13: 10 | D13: ʿĀLIYAH | E13: TEAM C | F13: Active | G13: =SUMPRODUCT(COUNTIFS(PROGRAM_DIRECTORY!$A$2:$A$334, $N13:$AB13, PROGRAM_DIRECTORY!$D$2:$D$334, "Non-Stage", PROGRAM_DIRECTORY!$E$2:$E$334, "Individual")) -> 0 | H13: =SUMPRODUCT(COUNTIFS(PROGRAM_DIRECTORY!$A$2:$A$334, $N13:$AB13, PROGRAM_DIRECTORY!$D$2:$D$334, "Stage", PROGRAM_DIRECTORY!$E$2:$E$334, "Individual")) -> 0 | I13: =SUMPRODUCT(COUNTIFS(PROGRAM_DIRECTORY!$A$2:$A$334, $N13:$AB13, PROGRAM_DIRECTORY!$D$2:$D$334, "Sports")) -> 0 | J13: =SUMPRODUCT(COUNTIFS(PROGRAM_DIRECTORY!$A$2:$A$334, $N13:$AB13, PROGRAM_DIRECTORY!$E$2:$E$334, "Individual")) -> 0 | K13: =SUMPRODUCT(COUNTIFS(PROGRAM_DIRECTORY!$A$2:$A$334, $N13:$AB13, PROGRAM_DIRECTORY!$E$2:$E$334, "Group")) -> 0 | L13: =COUNTIF($N13:$AB13, "<>") -> 0 | M13: =IF($F13<>"Active", "Inactive Student", IF($J13>IF(OR($D13="BIDĀYAH", $D13="BIDAYAH"), 12, IF(OR($D13="THĀNAWIYYAH", $D13="THANAWIYYAH"), 10, 9)), "Individual Quota Exceeded", IF($G13>IF(OR($D13="BIDĀYAH", $D13="BIDAYAH"), 8, IF(OR($D13="THĀNAWIYYAH", $D13="THANAWIYYAH"), 6, 5)), "Non-Stage Quota Exceeded", IF($H13>4, "Stage Quota Exceeded", IF(AND($H13=0, $G13=0), "Min 1 Required (Stage & Non-Stage)", IF($H13=0, "Min 1 Required (Stage)", IF($G13=0, "Min 1 Required (Non-Stage)", "Compliant"))))))) -> Min 1 Required (Stage & Non-Stage) | AC13: =TEXTJOIN(", ", TRUE, $N13:$AB13)
... A294: 487 | B294: RAHIL RAYAN P | C294: 1 | D294: BIDĀYAH | E294: TEAM C | F294: Active | G294: =SUMPRODUCT(COUNTIFS(PROGRAM_DIRECTORY!$A$2:$A$334, $N294:$AB294, PROGRAM_DIRECTORY!$D$2:$D$334, "Non-Stage", PROGRAM_DIRECTORY!$E$2:$E$334, "Individual")) -> 0 | H294: =SUMPRODUCT(COUNTIFS(PROGRAM_DIRECTORY!$A$2:$A$334, $N294:$AB294, PROGRAM_DIRECTORY!$D$2:$D$334, "Stage", PROGRAM_DIRECTORY!$E$2:$E$334, "Individual")) -> 0 | I294: =SUMPRODUCT(COUNTIFS(PROGRAM_DIRECTORY!$A$2:$A$334, $N294:$AB294, PROGRAM_DIRECTORY!$D$2:$D$334, "Sports")) -> 0 | J294: =SUMPRODUCT(COUNTIFS(PROGRAM_DIRECTORY!$A$2:$A$334, $N294:$AB294, PROGRAM_DIRECTORY!$E$2:$E$334, "Individual")) -> 0 | K294: =SUMPRODUCT(COUNTIFS(PROGRAM_DIRECTORY!$A$2:$A$334, $N294:$AB294, PROGRAM_DIRECTORY!$E$2:$E$334, "Group")) -> 0 | L294: =COUNTIF($N294:$AB294, "<>") -> 0 | M294: =IF($F294<>"Active", "Inactive Student", IF($J294>IF(OR($D294="BIDĀYAH", $D294="BIDAYAH"), 12, IF(OR($D294="THĀNAWIYYAH", $D294="THANAWIYYAH"), 10, 9)), "Individual Quota Exceeded", IF($G294>IF(OR($D294="BIDĀYAH", $D294="BIDAYAH"), 8, IF(OR($D294="THĀNAWIYYAH", $D294="THANAWIYYAH"), 6, 5)), "Non-Stage Quota Exceeded", IF($H294>4, "Stage Quota Exceeded", IF(AND($H294=0, $G294=0), "Min 1 Required (Stage & Non-Stage)", IF($H294=0, "Min 1 Required (Stage)", IF($G294=0, "Min 1 Required (Non-Stage)", "Compliant"))))))) -> Min 1 Required (Stage & Non-Stage) | AC294: =TEXTJOIN(", ", TRUE, $N294:$AB294)

Sheet PROGRAM_DIRECTORY
A1: Code | B1: Name | C1: Category | D1: Type | E1: Format | F1: Quota | G1: Group Size | H1: Max Participants | I1: Eligible Category | J1: Status
A2: BS1 | B2: QIRA'ATH | C2: BIDĀYAH | D2: Stage | E2: Individual | F2: 1 | G2: 1 | H2: 1 | I2: BIDĀYAH | J2: Active
A3: BS2 | B3: HIFZ | C3: BIDĀYAH | D3: Stage | E3: Individual | F3: 1 | G3: 1 | H3: 1 | I3: BIDĀYAH | J3: Active
A4: BS3 | B4: ADHAN | C4: BIDĀYAH | D4: Stage | E4: Individual | F4: 1 | G4: 1 | H4: 1 | I4: BIDĀYAH | J4: Active
A5: BS4 | B5: SONG MLM | C5: BIDĀYAH | D5: Stage | E5: Individual | F5: 1 | G5: 1 | H5: 1 | I5: BIDĀYAH | J5: Active
A6: BS5 | B6: SONG ARB | C6: BIDĀYAH | D6: Stage | E6: Individual | F6: 1 | G6: 1 | H6: 1 | I6: BIDĀYAH | J6: Active
A7: BS6 | B7: SONG URD | C7: BIDĀYAH | D7: Stage | E7: Individual | F7: 1 | G7: 1 | H7: 1 | I7: BIDĀYAH | J7: Active
A8: BS7 | B8: SPEECH MLM | C8: BIDĀYAH | D8: Stage | E8: Individual | F8: 1 | G8: 1 | H8: 1 | I8: BIDĀYAH | J8: Active
A9: BS8 | B9: SPEECH ENG | C9: BIDĀYAH | D9: Stage | E9: Individual | F9: 1 | G9: 1 | H9: 1 | I9: BIDĀYAH | J9: Active
A10: BS9 | B10: SPEECH ARB | C10: BIDĀYAH | D10: Stage | E10: Individual | F10: 1 | G10: 1 | H10: 1 | I10: BIDĀYAH | J10: Active
A11: BS10 | B11: SPEECH URD | C11: BIDĀYAH | D11: Stage | E11: Individual | F11: 1 | G11: 1 | H11: 1 | I11: BIDĀYAH | J11: Active
A12: BS11 | B12: WA'Z | C12: BIDĀYAH | D12: Stage | E12: Individual | F12: 1 | G12: 1 | H12: 1 | I12: BIDĀYAH | J12: Active
A13: BS12 | B13: READING ENG | C13: BIDĀYAH | D13: Stage | E13: Individual | F13: 1 | G13: 1 | H13: 1 | I13: BIDĀYAH | J13: Active
... A18: BS17 | B18: MATHS TALENT | C18: BIDĀYAH | D18: Stage | E18: Individual | F18: 2 | G18: 1 | H18: 2 | I18: BIDĀYAH | J18: Active
A19: BS18 | B19: CONVERSATION MLM | C19: BIDĀYAH | D19: Stage | E19: Individual | F19: 1*2 | G19: 2 | H19: 2 | I19: BIDĀYAH | J19: Active
A20: BS19 | B20: GROUP SONG | C20: BIDĀYAH | D20: Stage | E20: Group | F20: 1*3 | G20: 3 | H20: 3 | I20: BIDĀYAH | J20: Active
A21: BS20 | B21: SPEECH & SONG MLM | C21: BIDĀYAH | D21: Stage | E21: Group | F21: 1*3 | G21: 3 | H21: 3 | I21: BIDĀYAH | J21: Active
A22: US1 | B22: QIRA'AH | C22: ʾŪLĀ | D22: Stage | E22: Individual | F22: 2 | G22: 1 | H22: 2 | I22: ʾŪLĀ | J22: Active
A23: US2 | B23: HIFZ | C23: ʾŪLĀ | D23: Stage | E23: Individual | F23: 2 | G23: 1 | H23: 2 | I23: ʾŪLĀ | J23: Active
A24: US3 | B24: SONG MLM | C24: ʾŪLĀ | D24: Stage | E24: Individual | F24: 2 | G24: 1 | H24: 2 | I24: ʾŪLĀ | J24: Active
A25: US4 | B25: SONG ENG | C25: ʾŪLĀ | D25: Stage | E25: Individual | F25: 2 | G25: 1 | H25: 2 | I25: ʾŪLĀ | J25: Active
A26: US5 | B26: SONG ARB | C26: ʾŪLĀ | D26: Stage | E26: Individual | F26: 2 | G26: 1 | H26: 2 | I26: ʾŪLĀ | J26: Active
A27: US6 | B27: SONG URD | C27: ʾŪLĀ | D27: Stage | E27: Individual | F27: 2 | G27: 1 | H27: 2 | I27: ʾŪLĀ | J27: Active
A28: US7 | B28: SPEECH MLM | C28: ʾŪLĀ | D28: Stage | E28: Individual | F28: 2 | G28: 1 | H28: 2 | I28: ʾŪLĀ | J28: Active
A29: US8 | B29: SPEECH ENG | C29: ʾŪLĀ | D29: Stage | E29: Individual | F29: 2 | G29: 1 | H29: 2 | I29: ʾŪLĀ | J29: Active
A30: US9 | B30: SPEECH ARB | C30: ʾŪLĀ | D30: Stage | E30: Individual | F30: 2 | G30: 1 | H30: 2 | I30: ʾŪLĀ | J30: Active
A31: US10 | B31: SPEECH URD | C31: ʾŪLĀ | D31: Stage | E31: Individual | F31: 2 | G31: 1 | H31: 2 | I31: ʾŪLĀ | J31: Active
A32: US11 | B32: WA'Z | C32: ʾŪLĀ | D32: Stage | E32: Individual | F32: 2 | G32: 1 | H32: 2 | I32: ʾŪLĀ | J32: Active
A33: US12 | B33: PADHYAPARAYANAM | C33: ʾŪLĀ | D33: Stage | E33: Individual | F33: 2 | G33: 1 | H33: 2 | I33: ʾŪLĀ | J33: Active
... A43: US22 | B43: NJAN MALAYALI | C43: ʾŪLĀ | D43: Stage | E43: Individual | F43: 2 | G43: 1 | H43: 2 | I43: ʾŪLĀ | J43: Active
A44: US23 | B44: CONVERSATION ENG | C44: ʾŪLĀ | D44: Stage | E44: Individual | F44: 1*2 | G44: 2 | H44: 2 | I44: ʾŪLĀ | J44: Active
A45: US24 | B45: CONVERSATION ARB | C45: ʾŪLĀ | D45: Stage | E45: Individual | F45: 1*2 | G45: 2 | H45: 2 | I45: ʾŪLĀ | J45: Active
A46: US25 | B46: CONVERSATION URD | C46: ʾŪLĀ | D46: Stage | E46: Individual | F46: 1*2 | G46: 2 | H46: 2 | I46: ʾŪLĀ | J46: Active
A47: US26 | B47: GROUP SONG | C47: ʾŪLĀ | D47: Stage | E47: Group | F47: 1*3 | G47: 3 | H47: 3 | I47: ʾŪLĀ | J47: Active
A48: TS1 | B48: HIFZ & QIRA'AH | C48: THĀNIYAH | D48: Stage | E48: Individual | F48: 2 | G48: 1 | H48: 2 | I48: THĀNIYAH | J48: Active
A49: TS2 | B49: WA'Z | C49: THĀNIYAH | D49: Stage | E49: Individual | F49: 2 | G49: 1 | H49: 2 | I49: THĀNIYAH | J49: Active
A50: TS3 | B50: BHAKTHI GANAM | C50: THĀNIYAH | D50: Stage | E50: Individual | F50: 2 | G50: 1 | H50: 2 | I50: THĀNIYAH | J50: Active
A51: TS4 | B51: SONG ENG | C51: THĀNIYAH | D51: Stage | E51: Individual | F51: 2 | G51: 1 | H51: 2 | I51: THĀNIYAH | J51: Active
A52: TS5 | B52: SONG ARB | C52: THĀNIYAH | D52: Stage | E52: Individual | F52: 2 | G52: 1 | H52: 2 | I52: THĀNIYAH | J52: Active
A53: TS6 | B53: SONG URD | C53: THĀNIYAH | D53: Stage | E53: Individual | F53: 2 | G53: 1 | H53: 2 | I53: THĀNIYAH | J53: Active
...

Sheet REGISTRATION_DESK
A1: Category | B1: THĀNIYAH | D1: TOTAL STUDENTS | E1: COMPLIANT | F1: MIN 1 REQ | G1: OVER QUOTA | H1: TOTAL REG
A2: Program Type | B2: All Programs | D2: =COUNTIFS('MASTER LIST'!$D$2:$D$294, $B$1, 'MASTER LIST'!$E$2:$E$294, $B$3, 'MASTER LIST'!$F$2:$F$294, "Active") -> 17 | E2: =COUNTIFS('MASTER LIST'!$D$2:$D$294, $B$1, 'MASTER LIST'!$E$2:$E$294, $B$3, 'MASTER LIST'!$M$2:$M$294, "Compliant") -> 0 | F2: =COUNTIFS('MASTER LIST'!$D$2:$D$294, $B$1, 'MASTER LIST'!$E$2:$E$294, $B$3, 'MASTER LIST'!$M$2:$M$294, "Min 1 Required*") -> 17 | G2: =COUNTIFS('MASTER LIST'!$D$2:$D$294, $B$1, 'MASTER LIST'!$E$2:$E$294, $B$3, 'MASTER LIST'!$M$2:$M$294, "*Quota Exceeded*") -> 0 | H2: =SUMIF('MASTER LIST'!$E$2:$E$294, $B$3, 'MASTER LIST'!$L$2:$L$294) -> 0
A3: Team | B3: TEAM C | D3: Active in Team | E3: Meets All Bylaws | F3: Pending | G3: Violations | H3: Team Total
A4: Active Student Count | B4: =COUNTIFS('MASTER LIST'!$D$2:$D$294, $B$1, 'MASTER LIST'!$E$2:$E$294, $B$3, 'MASTER LIST'!$F$2:$F$294, "Active") -> 17
G5: =IFERROR(__xludf.DUMMYFUNCTION("IFERROR(TRANSPOSE(FILTER(PROGRAM_DIRECTORY!$A$2:$A$334, PROGRAM_DIRECTORY!$C$2:$C$334=$B$1, IF(OR($B$2=""All Programs"", $B$2=""All"", $B$2=""""), PROGRAM_DIRECTORY!$A$2:$A$334<>"""", PROGRAM_DIRECTORY!$D$2:$D$334=SWITCH($B$2, ""ST"", ""Stage"", ""FS"", "&"""Non-Stage"", ""Off-Stage"", ""Non-Stage"", ""SP"", ""Sports"", $B$2)))), """")"),"TS1") -> TS1 | H5: =IFERROR(__xludf.DUMMYFUNCTION("""COMPUTED_VALUE"""),"TS2") -> TS2 | I5: =IFERROR(__xludf.DUMMYFUNCTION("""COMPUTED_VALUE"""),"TS3") -> TS3 | J5: =IFERROR(__xludf.DUMMYFUNCTION("""COMPUTED_VALUE"""),"TS4") -> TS4 | K5: =IFERROR(__xludf.DUMMYFUNCTION("""COMPUTED_VALUE"""),"TS5") -> TS5 | L5: =IFERROR(__xludf.DUMMYFUNCTION("""COMPUTED_VALUE"""),"TS6") -> TS6 | M5: =IFERROR(__xludf.DUMMYFUNCTION("""COMPUTED_VALUE"""),"TS7") -> TS7 | N5: =IFERROR(__xludf.DUMMYFUNCTION("""COMPUTED_VALUE"""),"TS8") -> TS8 | O5: =IFERROR(__xludf.DUMMYFUNCTION("""COMPUTED_VALUE"""),"TS9") -> TS9 | P5: =IFERROR(__xludf.DUMMYFUNCTION("""COMPUTED_VALUE"""),"TS10") -> TS10 | Q5: =IFERROR(__xludf.DUMMYFUNCTION("""COMPUTED_VALUE"""),"TS11") -> TS11 | R5: =IFERROR(__xludf.DUMMYFUNCTION("""COMPUTED_VALUE"""),"TS12") -> TS12 | S5: =IFERROR(__xludf.DUMMYFUNCTION("""COMPUTED_VALUE"""),"TS13") -> TS13 | T5: =IFERROR(__xludf.DUMMYFUNCTION("""COMPUTED_VALUE"""),"TS14") -> TS14 | U5: =IFERROR(__xludf.DUMMYFUNCTION("""COMPUTED_VALUE"""),"TS15") -> TS15 | V5: =IFERROR(__xludf.DUMMYFUNCTION("""COMPUTED_VALUE"""),"TS16") -> TS16 | W5: =IFERROR(__xludf.DUMMYFUNCTION("""COMPUTED_VALUE"""),"TS17") -> TS17 | X5: =IFERROR(__xludf.DUMMYFUNCTION("""COMPUTED_VALUE"""),"TS18") -> TS18 | Y5: =IFERROR(__xludf.DUMMYFUNCTION("""COMPUTED_VALUE"""),"TS19") -> TS19 | Z5: =IFERROR(__xludf.DUMMYFUNCTION("""COMPUTED_VALUE"""),"TS20") -> TS20 | AA5: =IFERROR(__xludf.DUMMYFUNCTION("""COMPUTED_VALUE"""),"TS21") -> TS21 | AB5: =IFERROR(__xludf.DUMMYFUNCTION("""COMPUTED_VALUE"""),"TS22") -> TS22 | AC5: =IFERROR(__xludf.DUMMYFUNCTION("""COMPUTED_VALUE"""),"TS23") -> TS23 | AD5: =IFERROR(__xludf.DUMMYFUNCTION("""COMPUTED_VALUE"""),"TNS1") -> TNS1 | AE5: =IFERROR(__xludf.DUMMYFUNCTION("""COMPUTED_VALUE"""),"TNS2") -> TNS2 | AF5: =IFERROR(__xludf.DUMMYFUNCTION("""COMPUTED_VALUE"""),"TNS3") -> TNS3 | AG5: =IFERROR(__xludf.DUMMYFUNCTION("""COMPUTED_VALUE"""),"TNS4") -> TNS4 | AH5: =IFERROR(__xludf.DUMMYFUNCTION("""COMPUTED_VALUE"""),"TNS5") -> TNS5 | AI5: =IFERROR(__xludf.DUMMYFUNCTION("""COMPUTED_VALUE"""),"TNS6") -> TNS6 | AJ5: =IFERROR(__xludf.DUMMYFUNCTION("""COMPUTED_VALUE"""),"TNS7") -> TNS7 | AK5: =IFERROR(__xludf.DUMMYFUNCTION("""COMPUTED_VALUE"""),"TNS8") -> TNS8 | AL5: =IFERROR(__xludf.DUMMYFUNCTION("""COMPUTED_VALUE"""),"TNS9") -> TNS9 | AM5: =IFERROR(__xludf.DUMMYFUNCTION("""COMPUTED_VALUE"""),"TNS10") -> TNS10 | AN5: =IFERROR(__xludf.DUMMYFUNCTION("""COMPUTED_VALUE"""),"TNS11") -> TNS11 | AO5: =IFERROR(__xludf.DUMMYFUNCTION("""COMPUTED_VALUE"""),"TNS12") -> TNS12 | AP5: =IFERROR(__xludf.DUMMYFUNCTION("""COMPUTED_VALUE"""),"TNS13") -> TNS13 | AQ5: =IFERROR(__xludf.DUMMYFUNCTION("""COMPUTED_VALUE"""),"TNS14") -> TNS14 | AR5: =IFERROR(__xludf.DUMMYFUNCTION("""COMPUTED_VALUE"""),"TNS15") -> TNS15 | AS5: =IFERROR(__xludf.DUMMYFUNCTION("""COMPUTED_VALUE"""),"TNS16") -> TNS16 | AT5: =IFERROR(__xludf.DUMMYFUNCTION("""COMPUTED_VALUE"""),"TNS17") -> TNS17 | AU5: =IFERROR(__xludf.DUMMYFUNCTION("""COMPUTED_VALUE"""),"TNS18") -> TNS18 | AV5: =IFERROR(__xludf.DUMMYFUNCTION("""COMPUTED_VALUE"""),"TNS19") -> TNS19 | AW5: =IFERROR(__xludf.DUMMYFUNCTION("""COMPUTED_VALUE"""),"TNS20") -> TNS20 | AX5: =IFERROR(__xludf.DUMMYFUNCTION("""COMPUTED_VALUE"""),"TNS21") -> TNS21 | AY5: =IFERROR(__xludf.DUMMYFUNCTION("""COMPUTED_VALUE"""),"TNS22") -> TNS22 | AZ5: =IFERROR(__xludf.DUMMYFUNCTION("""COMPUTED_VALUE"""),"TNS23") -> TNS23 | BA5: =IFERROR(__xludf.DUMMYFUNCTION("""COMPUTED_VALUE"""),"TNS24") -> TNS24 | BB5: =IFERROR(__xludf.DUMMYFUNCTION("""COMPUTED_VALUE"""),"TSP1") -> TSP1 | BC5: =IFERROR(__xludf.DUMMYFUNCTION("""COMPUTED_VALUE"""),"TSP2") -> TSP2 | BD5: =IFERROR(__xludf.DUMMYFUNCTION("""COMPUTED_VALUE"""),"TSP3") -> TSP3 | BE5: =IFERROR(__xludf.DUMMYFUNCTION("""COMPUTED_VALUE"""),"TSP4") -> TSP4 | BF5: =IFERROR(__xludf.DUMMYFUNCTION("""COMPUTED_VALUE"""),"TSP5") -> TSP5 | BG5: =IFERROR(__xludf.DUMMYFUNCTION("""COMPUTED_VALUE"""),"TSP6") -> TSP6 | BH5: =IFERROR(__xludf.DUMMYFUNCTION("""COMPUTED_VALUE"""),"TSP7") -> TSP7 | BI5: =IFERROR(__xludf.DUMMYFUNCTION("""COMPUTED_VALUE"""),"TSP8") -> TSP8 | BJ5: =IFERROR(__xludf.DUMMYFUNCTION("""COMPUTED_VALUE"""),"TSP9") -> TSP9 | BK5: =IFERROR(__xludf.DUMMYFUNCTION("""COMPUTED_VALUE"""),"TSP10") -> TSP10 | BL5: =IFERROR(__xludf.DUMMYFUNCTION("""COMPUTED_VALUE"""),"TSP11") -> TSP11 | BM5: =IFERROR(__xludf.DUMMYFUNCTION("""COMPUTED_VALUE"""),"TSP12") -> TSP12 | BN5: =IFERROR(__xludf.DUMMYFUNCTION("""COMPUTED_VALUE"""),"TSP13") -> TSP13 | BO5: =IFERROR(__xludf.DUMMYFUNCTION("""COMPUTED_VALUE"""),"TSP14") -> TSP14
A6: AD NO | B6: STUDENT NAME | C6: CLASS | D6: CATEGORY | E6: TEAM | F6: BYLAW STATUS | G6: =IFERROR(__xludf.DUMMYFUNCTION("IFERROR(TRANSPOSE(FILTER(PROGRAM_DIRECTORY!$B$2:$B$334 & "" ("" & PROGRAM_DIRECTORY!$F$2:$F$334 & "")"", PROGRAM_DIRECTORY!$C$2:$C$334=$B$1, IF(OR($B$2=""All Programs"", $B$2=""All"", $B$2=""""), PROGRAM_DIRECTORY!$A$2:$A$334<>"""", PROGRAM_DIRECTORY!$D$2"&":$D$334=SWITCH($B$2, ""ST"", ""Stage"", ""FS"", ""Non-Stage"", ""Off-Stage"", ""Non-Stage"", ""SP"", ""Sports"", $B$2)))), """")"),"HIFZ & QIRA'AH (2)") -> HIFZ & QIRA'AH (2) | H6: =IFERROR(__xludf.DUMMYFUNCTION("""COMPUTED_VALUE"""),"WA'Z (2)") -> WA'Z (2) | I6: =IFERROR(__xludf.DUMMYFUNCTION("""COMPUTED_VALUE"""),"BHAKTHI GANAM (2)") -> BHAKTHI GANAM (2) | J6: =IFERROR(__xludf.DUMMYFUNCTION("""COMPUTED_VALUE"""),"SONG ENG (2)") -> SONG ENG (2) | K6: =IFERROR(__xludf.DUMMYFUNCTION("""COMPUTED_VALUE"""),"SONG ARB (2)") -> SONG ARB (2) | L6: =IFERROR(__xludf.DUMMYFUNCTION("""COMPUTED_VALUE"""),"SONG URD (2)") -> SONG URD (2) | M6: =IFERROR(__xludf.DUMMYFUNCTION("""COMPUTED_VALUE"""),"SPEECH MLM (2)") -> SPEECH MLM (2) | N6: =IFERROR(__xludf.DUMMYFUNCTION("""COMPUTED_VALUE"""),"SPEECH ENG (2)") -> SPEECH ENG (2) | O6: =IFERROR(__xludf.DUMMYFUNCTION("""COMPUTED_VALUE"""),"SPEECH ARB (2)") -> SPEECH ARB (2) | P6: =IFERROR(__xludf.DUMMYFUNCTION("""COMPUTED_VALUE"""),"SPEECH URD (2)") -> SPEECH URD (2) | Q6: =IFERROR(__xludf.DUMMYFUNCTION("""COMPUTED_VALUE"""),"PADHYAPARAYANAM (2)") -> PADHYAPARAYANAM (2) | R6: =IFERROR(__xludf.DUMMYFUNCTION("""COMPUTED_VALUE"""),"HISTORY TALK ENG (2)") -> HISTORY TALK ENG (2) | S6: =IFERROR(__xludf.DUMMYFUNCTION("""COMPUTED_VALUE"""),"ORU NIMISHAM (2)") -> ORU NIMISHAM (2) | T6: =IFERROR(__xludf.DUMMYFUNCTION("""COMPUTED_VALUE"""),"NEWS WRITING AND READING MLM (2)") -> NEWS WRITING AND READING MLM (2) | U6: =IFERROR(__xludf.DUMMYFUNCTION("""COMPUTED_VALUE"""),"SPELLING BEE (2)") -> SPELLING BEE (2) | V6: =IFERROR(__xludf.DUMMYFUNCTION("""COMPUTED_VALUE"""),"GK QUIZ (2)") -> GK QUIZ (2) | W6: =IFERROR(__xludf.DUMMYFUNCTION("""COMPUTED_VALUE"""),"SCIENCE MASTER (2)") -> SCIENCE MASTER (2) | X6: =IFERROR(__xludf.DUMMYFUNCTION("""COMPUTED_VALUE"""),"GRAMMAR QUIZ (2)") -> GRAMMAR QUIZ (2) | Y6: =IFERROR(__xludf.DUMMYFUNCTION("""COMPUTED_VALUE"""),"MATHS TALENT (2)") -> MATHS TALENT (2) | Z6: =IFERROR(__xludf.DUMMYFUNCTION("""COMPUTED_VALUE"""),"SWARF IQ (2)") -> SWARF IQ (2) | AA6: =IFERROR(__xludf.DUMMYFUNCTION("""COMPUTED_VALUE"""),"PADAPPATTU (2)") -> PADAPPATTU (2) | AB6: =IFERROR(__xludf.DUMMYFUNCTION("""COMPUTED_VALUE"""),"SPEECH & SONG MLM (1*3)") -> SPEECH & SONG MLM (1*3) | AC6: =IFERROR(__xludf.DUMMYFUNCTION("""COMPUTED_VALUE"""),"GROUP SONG (1*4)") -> GROUP SONG (1*4) | AD6: =IFERROR(__xludf.DUMMYFUNCTION("""COMPUTED_VALUE"""),"SENTENCE TRANSLATION (2)") -> SENTENCE TRANSLATION (2) | AE6: =IFERROR(__xludf.DUMMYFUNCTION("""COMPUTED_VALUE"""),"ACRYLIC PAINTING (2)") -> ACRYLIC PAINTING (2) | AF6: =IFERROR(__xludf.DUMMYFUNCTION("""COMPUTED_VALUE"""),"ESSAY MLM (2)") -> ESSAY MLM (2) | AG6: =IFERROR(__xludf.DUMMYFUNCTION("""COMPUTED_VALUE"""),"ESSAY ENG (2)") -> ESSAY ENG (2) | AH6: =IFERROR(__xludf.DUMMYFUNCTION("""COMPUTED_VALUE"""),"ESSAY ARB (2)") -> ESSAY ARB (2) | AI6: =IFERROR(__xludf.DUMMYFUNCTION("""COMPUTED_VALUE"""),"ESSAY URD (2)") -> ESSAY URD (2) | AJ6: =IFERROR(__xludf.DUMMYFUNCTION("""COMPUTED_VALUE"""),"ESSAY HINDI (2)") -> ESSAY HINDI (2) | AK6: =IFERROR(__xludf.DUMMYFUNCTION("""COMPUTED_VALUE"""),"POEM MLM (2)") -> POEM MLM (2) | AL6: =IFERROR(__xludf.DUMMYFUNCTION("""COMPUTED_VALUE"""),"POEM ENG (2)") -> POEM ENG (2) | AM6: =IFERROR(__xludf.DUMMYFUNCTION("""COMPUTED_VALUE"""),"POEM ARB (2)") -> POEM ARB (2) | AN6: =IFERROR(__xludf.DUMMYFUNCTION("""COMPUTED_VALUE"""),"POEM URD (2)") -> POEM URD (2) | AO6: =IFERROR(__xludf.DUMMYFUNCTION("""COMPUTED_VALUE"""),"SHORT STORY MLM (2)") -> SHORT STORY MLM (2) | AP6: =IFERROR(__xludf.DUMMYFUNCTION("""COMPUTED_VALUE"""),"SHORT STORY ENG (2)") -> SHORT STORY ENG (2) | AQ6: =IFERROR(__xludf.DUMMYFUNCTION("""COMPUTED_VALUE"""),"SHORT STORY ARB (2)") -> SHORT STORY ARB (2) | AR6: =IFERROR(__xludf.DUMMYFUNCTION("""COMPUTED_VALUE"""),"SHORT STORY URD (2)") -> SHORT STORY URD (2) | AS6: =IFERROR(__xludf.DUMMYFUNCTION("""COMPUTED_VALUE"""),"TEXT TORNADO (2)") -> TEXT TORNADO (2) | AT6: =IFERROR(__xludf.DUMMYFUNCTION("""COMPUTED_VALUE"""),"CARTOON (2)") -> CARTOON (2) | AU6: =IFERROR(__xludf.DUMMYFUNCTION("""COMPUTED_VALUE"""),"DICTIONARY MAKING HINDI (2)") -> DICTIONARY MAKING HINDI (2) | AV6: =IFERROR(__xludf.DUMMYFUNCTION("""COMPUTED_VALUE"""),"EXCEL MASTER (2)") -> EXCEL MASTER (2) | AW6: =IFERROR(__xludf.DUMMYFUNCTION("""COMPUTED_VALUE"""),"POSTER DESIGNING (2)") -> POSTER DESIGNING (2) | AX6: =IFERROR(__xludf.DUMMYFUNCTION("""COMPUTED_VALUE"""),"VIDEO EDITING (2)") -> VIDEO EDITING (2) | AY6: =IFERROR(__xludf.DUMMYFUNCTION("""COMPUTED_VALUE"""),"IMAGE ELABORATION ENG (2)") -> IMAGE ELABORATION ENG (2) | AZ6: =IFERROR(__xludf.DUMMYFUNCTION("""COMPUTED_VALUE"""),"INSTANT CHILDREN'S MAGAZINE MLM (1*5)") -> INSTANT CHILDREN'S MAGAZINE MLM (1*5) | BA6: =IFERROR(__xludf.DUMMYFUNCTION("""COMPUTED_VALUE"""),"INSTANT NEWSPAPER MLM (1*5)") -> INSTANT NEWSPAPER MLM (1*5) | BB6: =IFERROR(__xludf.DUMMYFUNCTION("""COMPUTED_VALUE"""),"200M Running (2)") -> 200M Running (2) | BC6: =IFERROR(__xludf.DUMMYFUNCTION("""COMPUTED_VALUE"""),"Long Jump (2)") -> Long Jump (2) | BD6: =IFERROR(__xludf.DUMMYFUNCTION("""COMPUTED_VALUE"""),"4 × 100M Relay (2)") -> 4 × 100M Relay (2) | BE6: =IFERROR(__xludf.DUMMYFUNCTION("""COMPUTED_VALUE"""),"Sack Race (2)") -> Sack Race (2) | BF6: =IFERROR(__xludf.DUMMYFUNCTION("""COMPUTED_VALUE"""),"Shootout (2)") -> Shootout (2) | BG6: =IFERROR(__xludf.DUMMYFUNCTION("""COMPUTED_VALUE"""),"Badminton (2)") -> Badminton (2) | BH6: =IFERROR(__xludf.DUMMYFUNCTION("""COMPUTED_VALUE"""),"Plank (2)") -> Plank (2) | BI6: =IFERROR(__xludf.DUMMYFUNCTION("""COMPUTED_VALUE"""),"Juggling (2)") -> Juggling (2) | BJ6: =IFERROR(__xludf.DUMMYFUNCTION("""COMPUTED_VALUE"""),"Throw to stump (2)") -> Throw to stump (2) | BK6: =IFERROR(__xludf.DUMMYFUNCTION("""COMPUTED_VALUE"""),"Pot breaking (2)") -> Pot breaking (2) | BL6: =IFERROR(__xludf.DUMMYFUNCTION("""COMPUTED_VALUE"""),"Slow Race (2)") -> Slow Race (2) | BM6: =IFERROR(__xludf.DUMMYFUNCTION("""COMPUTED_VALUE"""),"Water Filling Group (2)") -> Water Filling Group (2) | BN6: =IFERROR(__xludf.DUMMYFUNCTION("""COMPUTED_VALUE"""),"Arm wrestling (2)") -> Arm wrestling (2) | BO6: =IFERROR(__xludf.DUMMYFUNCTION("""COMPUTED_VALUE"""),"Footsall (1*4)") -> Footsall (1*4)
